Workbook

Sheet Mentah
A1: company_name | B1: Customer OMS ID | C1: Admin_Email | D1: OMS Document Name | E1: document_name | F1: uploaded_file | G1: expired_date | H1: status | L1: Email | M1: OMS Customer ID
A2: Apotik Bahagia | B2: #N/A | C2: arie_4121mel@yahoo.com | D2: siup_nib | E2: document_siup | F2: /legal_documents/company/3921/document_siup.pdf | H2: pending | L2: svrizkyp007@gmail.com | M2: -
A3: Apotik Bahagia | B3: #N/A | C3: arie_4121mel@yahoo.com | D3: sipa | E3: document_sipa_sika_apoteker | F3: /legal_documents/company/3921/document_sipa_sika_apoteker.jpg | H3: pending | L3: farmasi@rsborromeus.com | M3: RS SANTO BORROMEUS -
A4: PKU MUHAMMADIYAH SRUWENG | B4: #N/A | C4: pkumuhsruweng1@gmail.com | D4: siup_nib | E4: document_siup | F4: /legal_documents/company/2745/document_siup.png | G4: 46024 | H4: pending | L4: logfar.grhabunda@gmail.com | M4: RSIA GRHA BUNDA -
A5: PKU MUHAMMADIYAH SRUWENG | B5: #N/A | C5: pkumuhsruweng1@gmail.com | D5: sipa | E5: document_sipa_sika_apoteker | F5: /legal_documents/company/2745/document_sipa_sika_apoteker.jpeg | G5: 46024 | H5: pending | L5: medika.antapani@gmail.com | M5: KLINIK UTAMA MEDIKA ANTAPANI -
A6: PKU MUHAMMADIYAH SRUWENG | B6: #N/A | C6: pkumuhsruweng1@gmail.com | D6: stra | E6: document_stra_apoteker | F6: /legal_documents/company/2745/document_stra_apoteker.jpeg | G6: 46024 | H6: pending | L6: nusafarma.apotek@gmail.com | M6: APOTEK NUSA FARMA -
A7: PKU MUHAMMADIYAH SRUWENG | B7: #N/A | C7: pkumuhsruweng1@gmail.com | D7: npwp_file | E7: document_npwp | F7: /legal_documents/company/2745/document_npwp.jpeg | H7: pending | L7: sekretariat.rsai@gmail.com | M7: RS AL ISLAM BANDUNG -
A8: PKU MUHAMMADIYAH SRUWENG | B8: #N/A | C8: pkumuhsruweng1@gmail.com | E8: document_nama_apoteker_penanggung_jawab | F8: /legal_documents/company/2745/document_nama_apoteker_penanggung_jawab.pdf | H8: pending | L8: marketing@edelweiss.id | M8: RUMAH SAKIT EDELWEISS -
A9: PKU MUHAMMADIYAH SRUWENG | B9: #N/A | C9: pkumuhsruweng1@gmail.com | E9: document_form_spesiment | F9: /legal_documents/company/2745/document_form_spesiment.jpeg | H9: pending | L9: halo@mutiaracikutra.com | M9: KLINIK MUTIARA CIKUTRA -
A10: Apotek wijaya kusuma | B10: #N/A | C10: karsanti1607@gmail.com | D10: siup_nib | E10: document_siup | F10: /legal_documents/company/3923/document_siup.jpg | G10: 45880 | H10: pending | L10: rspcirebon@rspelabuhan.com | M10: RUMAH SAKIT UMUM PELABUHAN CIREBON - - 1
A11: Apotek wijaya kusuma | B11: #N/A | C11: karsanti1607@gmail.com | D11: sipa | E11: document_sipa_sika_apoteker | F11: /legal_documents/company/3923/document_sipa_sika_apoteker.jpg | G11: 45681 | H11: pending | L11: sekertariat@rsudbandungkiwari.or.id | M11: BANDUNG KIWARI -
A12: Apotek wijaya kusuma | B12: #N/A | C12: karsanti1607@gmail.com | D12: surat_izin_operasional | E12: document_surat_izin_apotek | F12: /legal_documents/company/3923/document_surat_izin_apotek.jpg | G12: 45681 | H12: pending | L12: rantisarnita@yahoo.com | M12: APOTEK SERAVI -
A13: Apotek wijaya kusuma | B13: #N/A | C13: karsanti1607@gmail.com | D13: npwp_file | E13: document_npwp | F13: /legal_documents/company/3923/document_npwp.jpg | H13: pending | L13: abufauzan374@gmail.com | M13: APOTEK REFAH -
A14: Apotek wijaya kusuma | B14: #N/A | C14: karsanti1607@gmail.com | E14: document_form_spesiment | F14: /legal_documents/company/3923/document_form_spesiment.jpg | H14: pending | L14: adm.kasihbunda@gmail.com | M14: RSU KASIH BUNDA -
A15: Apotek wijaya kusuma | B15: #N/A | C15: karsanti1607@gmail.com | E15: document_nama_apoteker_penanggung_jawab | F15: /legal_documents/company/3923/document_nama_apoteker_penanggung_jawab.jpg | H15: pending | L15: alifia_klinik@yahoo.com | M15: APOTEK ALIFIA -
A16: Apotek wijaya kusuma | B16: #N/A | C16: karsanti1607@gmail.com | D16: foto_lokasi_bangunan_fisik | E16: document_foto_lokasi_bagunan_fisik | F16: /legal_documents/company/3923/document_foto_lokasi_bagunan_fisik.jpg | H16: pending | L16: apotek.almasoem@yahoo.co.id | M16: AL MASOEM 2 -
A17: RSU PURBOWANGI | B17: #N/A | C17: rsupurbowangigmb@gmail.com | D17: siup_nib | E17: document_siup | F17: /legal_documents/company/3754/document_siup.pdf | G17: 46470 | H17: pending | L17: apotekbunayya@gmail.com | M17: APOTEK BUNAYYA
A18: RSU PURBOWANGI | B18: #N/A | C18: rsupurbowangigmb@gmail.com | D18: npwp_file | E18: document_npwp | F18: /legal_documents/company/3754/document_npwp.jpeg | H18: pending | L18: armadamedikasejahtera@gmail.com | M18: KLINIK ARMADA MEDIKA SEJAHTERA -
A19: RSU PURBOWANGI | B19: #N/A | C19: rsupurbowangigmb@gmail.com | E19: document_nama_apoteker_penanggung_jawab | F19: /legal_documents/company/3754/document_nama_apoteker_penanggung_jawab.pdf | H19: pending | L19: farmasimelongasih@gmail.com | M19: KLINIK UTAMA IBU DAN ANAK MELONG ASIH -
A20: RSU PURBOWANGI | B20: #N/A | C20: rsupurbowangigmb@gmail.com | E20: document_form_spesiment | F20: /legal_documents/company/3754/document_form_spesiment.pdf | H20: pending | L20: klinik.alfatih@gmail.com | M20: APOTEK ALFATIH FARMA -
A21: RSU PURBOWANGI | B21: #N/A | C21: rsupurbowangigmb@gmail.com | D21: foto_lokasi_bangunan_fisik | E21: document_foto_lokasi_bagunan_fisik | F21: /legal_documents/company/3754/document_foto_lokasi_bagunan_fisik.pdf | H21: pending | L21: soffiarianti@gmail.com | M21: Apotek Cornel Sehat -
A22: Apotek Mitra Sehat Farma | B22: #N/A | C22: yuniatianes@gmail.com | D22: siup_nib | E22: document_siup | F22: /legal_documents/company/3919/document_siup.pdf | G22: 45291 | H22: pending | L22: sekretariat@rsudbandungkiwari.or.id | M22: BANDUNG KIWARI - - 1
A23: Apotek Mitra Sehat Farma | B23: #N/A | C23: yuniatianes@gmail.com | D23: sipa | E23: document_sipa_sika_apoteker | F23: /legal_documents/company/3919/document_sipa_sika_apoteker.pdf | G23: 46567 | H23: pending | L23: telemedika.health.center@gmail.com | M23: KLINIK UTAMA THC -
A24: Apotek Mitra Sehat Farma | B24: #N/A | C24: yuniatianes@gmail.com | D24: stra | E24: document_stra_apoteker | F24: /legal_documents/company/3919/document_stra_apoteker.pdf | G24: 46567 | H24: pending | L24: klinikardamisehat@gmail.com | M24: Klinik Ardami Sehat -
A25: Apotek Mitra Sehat Farma | B25: #N/A | C25: yuniatianes@gmail.com | D25: surat_izin_operasional | E25: document_surat_izin_apotek | F25: /legal_documents/company/3919/document_surat_izin_apotek.pdf | G25: 47663 | H25: pending | L25: assyifa.safilla@intibios.com | M25: APOTEK INTIBIOS BANDUNG -
A26: Apotek Mitra Sehat Farma | B26: #N/A | C26: yuniatianes@gmail.com | D26: npwp_file | E26: document_npwp | F26: /legal_documents/company/3919/document_npwp.pdf | H26: pending | L26: farmasi.karawang@intibios.com | M26: KLINIK INTIBIOS KARAWANG - - 1
A27: Apotek Mitra Sehat Farma | B27: #N/A | C27: yuniatianes@gmail.com | E27: document_nama_apoteker_penanggung_jawab | F27: /legal_documents/company/3919/document_nama_apoteker_penanggung_jawab.pdf | H27: pending | L27: asshofa.purwakarta@gmail.com | M27: KLINIK AS-SHOFA -
A28: Apotek Mutiara Farma | B28: #N/A | C28: aptmutiarafarma1@gmail.com | D28: siup_nib | E28: document_siup | F28: /legal_documents/company/3926/document_siup.jpeg | G28: 46113 | H28: pending | L28: asri.klinik@gmail.com | M28: KLINIK ASRI -
A29: Apotek Mutiara Farma | B29: #N/A | C29: aptmutiarafarma1@gmail.com | D29: sipa | E29: document_sipa_sika_apoteker | F29: /legal_documents/company/3926/document_sipa_sika_apoteker.jpeg | G29: 46113 | H29: pending | L29: berlianbakti.klinik126@gmail.com | M29: KLINIK BERLIAN BAKTI -
A30: Apotek Mutiara Farma | B30: #N/A | C30: aptmutiarafarma1@gmail.com | D30: stra | E30: document_stra_apoteker | F30: /legal_documents/company/3926/document_stra_apoteker.jpeg | G30: 46113 | H30: pending | L30: imuni.indonesia@gmail.com | M30: KLINIK PRATAMA IMUNI -
A31: Apotek Mutiara Farma | B31: #N/A | C31: aptmutiarafarma1@gmail.com | D31: surat_izin_operasional | E31: document_surat_izin_apotek | F31: /legal_documents/company/3926/document_surat_izin_apotek.jpeg | G31: 46113 | H31: pending | L31: apotek.izzatul@gmail.com | M31: KLINIK IZZATUL -
A32: Apotek Mutiara Farma | B32: #N/A | C32: aptmutiarafarma1@gmail.com | D32: npwp_file | E32: document_npwp | F32: /legal_documents/company/3926/document_npwp.jpeg | H32: pending | L32: klinik24jampadjadjaran@gmail.com | M32: KLINIK PADJADJARAN -
A33: Apotek Mutiara Farma | B33: #N/A | C33: aptmutiarafarma1@gmail.com | E33: document_nama_apoteker_penanggung_jawab | F33: /legal_documents/company/3926/document_nama_apoteker_penanggung_jawab.jpeg | H33: pending | L33: klinikbonamitrakeluarga0@gmail.com | M33: APOTEK BONA MITRA KELUARGA -
A34: Apotek Mutiara Farma | B34: #N/A | C34: aptmutiarafarma1@gmail.com | E34: document_form_spesiment | F34: /legal_documents/company/3926/document_form_spesiment.jpeg | H34: pending | L34: instalasifarmasiklinik2020@gmail.com | M34: INSTALASI FARMASI KLINIK OMSA MEDIC DENP -
A35: Apotek Mutiara Farma | B35: #N/A | C35: aptmutiarafarma1@gmail.com | D35: foto_lokasi_bangunan_fisik | E35: document_foto_lokasi_bagunan_fisik | F35: /legal_documents/company/3926/document_foto_lokasi_bagunan_fisik.jpeg | H35: pending | L35: alfatihfarma26@gmail.com | M35: APOTEK AL FATIH FARMA -
A36: Apotek wijaya kusuma | B36: #N/A | C36: karsanti1607@gmail.com | D36: stra | E36: document_stra_apoteker | F36: /legal_documents/company/3923/document_stra_apoteker.jpg | G36: 45681 | H36: pending | L36: sagi.capri@yahoo.com | M36: PT. SAGI CAPRI
A37: APT. ADHI GUNA FARMA | B37: #N/A | C37: adhigunafarma.01@gmail.com | D37: siup_nib | E37: document_siup | F37: /legal_documents/company/2717/document_siup.pdf | G37: 46537 | H37: pending | L37: procurement@kftd.co.id | M37: PT KIMIA FARMA TRADING & DISTRIBUTION - - 8
A38: APT. ADHI GUNA FARMA | B38: #N/A | C38: adhigunafarma.01@gmail.com | D38: sipa | E38: document_sipa_sika_apoteker | F38: /legal_documents/company/2717/document_sipa_sika_apoteker.jpg | G38: 46537 | H38: pending | L38: isya.puspadevi@kftd.co.id | M38: Isya KFTD
A39: APT. ADHI GUNA FARMA | B39: #N/A | C39: adhigunafarma.01@gmail.com | D39: stra | E39: document_stra_apoteker | F39: /legal_documents/company/2717/document_stra_apoteker.jpg | G39: 46537 | H39: pending | L39: apotekharkel@gmail.com | M39: Harapan Keluarga
A40: APT. ADHI GUNA FARMA | B40: #N/A | C40: adhigunafarma.01@gmail.com | D40: surat_izin_operasional | E40: document_surat_izin_apotek | F40: /legal_documents/company/2717/document_surat_izin_apotek.jpg | G40: 46537 | H40: pending | L40: dianpuspitasari120112@gmail.com | M40: Dian Puspita sari
...

Sheet Mateng
A1: email | B1: _website | C1: _store | D1: website_id | E1: store_id | F1: ktp_pemilik | G1: siup_nib | H1: npwp_file | I1: sertifikat_cdob | J1: sertifikat_cdob_expired_date | K1: sertifikat_cdob_is_active | L1: sertifikat_cdob_oms_path | M1: sertifikat_cdakb | N1: sertifikat_cdakb_expired_date | O1: sertifikat_cdakb_is_active | P1: sertifikat_cdakb_oms_path | Q1: sipa | R1: sipa_expired_date | S1: sipa_is_active | T1: sipa_oms_path | U1: sipttk | V1: sipttk_expired_date | W1: sipttk_is_active | X1: sipttk_oms_path | Y1: stra | Z1: stra_expired_date | AA1: stra_is_active | AB1: stra_oms_path | AC1: strttk | AD1: strttk_expired_date | AE1: strttk_is_active | AF1: strttk_oms_path | AG1: ktp_apoteker | AH1: ktp_pj_alkes | AI1: foto_lokasi_bangunan_fisik | AJ1: nama_apoteker_penanggung_jawab | AK1: npwp | AL1: nama_pada_npwp | AM1: administrasi_alamat | AN1: administrasi_email | AO1: administrasi_kode_pos | AP1: nama_sarana | AQ1: administrasi_nomor_telepon | AR1: faktur_nama | AS1: faktur_kota | AT1: faktur_alamat | AU1: no_account_bank | AV1: nama_account_bank | AW1: nama_bank | AX1: sarana_nama_pelanggan | AY1: sarana_alamat | AZ1: sarana_kota | BA1: sarana_kode_pos | BB1: sarana_email | BC1: sarana_nomor_telepon | BD1: no_nib | BE1: no_sertifikat_cdob | BF1: no_sertifikat_cdakb | BG1: apoteker_email | BH1: no_sipa | BI1: nama_ttk | BJ1: kefarmasian_email | BK1: no_sipttk | BL1: no_nib_siup | BM1: erp_customer_id | BN1: photo_profile | BO1: photo_profile_oms_path | BP1: oms_customer_verification_id | BQ1: foto_lokasi_bangunan_fisik_oms_path | BR1: oms_contact_id | BS1: bpjs | BT1: bpjs_file | BU1: bpjs_file_expired_date | BV1: bpjs_file_oms_path | BW1: bpjs_file_is_active | BX1: surat_izin_operasional | BY1: surat_izin_operasional_oms_path | BZ1: surat_izin_operasional_expired_date | CA1: surat_izin_operasional_is_active | CB1: no_surat_izin_operasional | CC1: giro_cek | CD1: transfer_bank | CE1: tunai | CF1: customer_reject_reason | CG1: ktp_pemilik_oms_path | CH1: ktp_apoteker_oms_path | CI1: npwp_oms_path | CJ1: siup_nib_oms_path | CK1: npwp_file_oms_path | CL1: foto_lokasi_bangunan_fisik_expired_date | CM1: foto_lokasi_bangunan_fisik_is_active | CN1: ktp_apoteker_expired_date | CO1: ktp_apoteker_is_active | CP1: ktp_pemilik_expired_date | CQ1: ktp_pemilik_is_active | CR1: npwp_file_expired_date | CS1: npwp_file_is_active | CT1: is_payment_status | CU1: siup_nib_expired_date | CV1: siup_nib_is_active
A2: svrizkyp007@gmail.com | B2: base | C2: default | D2: 1 | E2: 1 | F2: =VLOOKUP(A2,TEMP!I:K,3,FALSE) -> #N/A | G2: =VLOOKUP(A2,TEMP!AR:AT,3,FALSE) -> #N/A | H2: =VLOOKUP(A2,TEMP!P:R,3,FALSE) -> #N/A | I2: =VLOOKUP(A2,TEMP!W:Y,3,FALSE) -> #N/A | M2: =VLOOKUP(A2,TEMP!AD:AF,3,FALSE) -> #N/A | Q2: =VLOOKUP(A2,TEMP!AK:AM,3,FALSE) -> #N/A | Y2: =VLOOKUP(A2,TEMP!AY:BA,3,FALSE) -> #N/A | AC2: =VLOOKUP(A2,TEMP!BF:BH,3,FALSE) -> #N/A | AI2: =VLOOKUP(A2,TEMP!B:D,3,FALSE) -> #N/A | BX2: =VLOOKUP(A2,TEMP!BM:BO,3,FALSE) -> #N/A
A3: farmasi@rsborromeus.com | B3: base | C3: default | D3: 1 | E3: 1 | F3: =VLOOKUP(A3,TEMP!I:K,3,FALSE) -> #N/A | G3: =VLOOKUP(A3,TEMP!AR:AT,3,FALSE) -> #N/A | H3: =VLOOKUP(A3,TEMP!P:R,3,FALSE) -> #N/A | I3: =VLOOKUP(A3,TEMP!W:Y,3,FALSE) -> #N/A | M3: =VLOOKUP(A3,TEMP!AD:AF,3,FALSE) -> #N/A | Q3: =VLOOKUP(A3,TEMP!AK:AM,3,FALSE) -> #N/A | Y3: =VLOOKUP(A3,TEMP!AY:BA,3,FALSE) -> #N/A | AC3: =VLOOKUP(A3,TEMP!BF:BH,3,FALSE) -> #N/A | AI3: =VLOOKUP(A3,TEMP!B:D,3,FALSE) -> #N/A | BX3: =VLOOKUP(A3,TEMP!BM:BO,3,FALSE) -> #N/A
A4: logfar.grhabunda@gmail.com | B4: base | C4: default | D4: 1 | E4: 1 | F4: =VLOOKUP(A4,TEMP!I:K,3,FALSE) -> #N/A | G4: =VLOOKUP(A4,TEMP!AR:AT,3,FALSE) -> #N/A | H4: =VLOOKUP(A4,TEMP!P:R,3,FALSE) -> #N/A | I4: =VLOOKUP(A4,TEMP!W:Y,3,FALSE) -> #N/A | M4: =VLOOKUP(A4,TEMP!AD:AF,3,FALSE) -> #N/A | Q4: =VLOOKUP(A4,TEMP!AK:AM,3,FALSE) -> #N/A | Y4: =VLOOKUP(A4,TEMP!AY:BA,3,FALSE) -> #N/A | AC4: =VLOOKUP(A4,TEMP!BF:BH,3,FALSE) -> #N/A | AI4: =VLOOKUP(A4,TEMP!B:D,3,FALSE) -> #N/A | BX4: =VLOOKUP(A4,TEMP!BM:BO,3,FALSE) -> #N/A
A5: medika.antapani@gmail.com | B5: base | C5: default | D5: 1 | E5: 1 | F5: =VLOOKUP(A5,TEMP!I:K,3,FALSE) -> #N/A | G5: =VLOOKUP(A5,TEMP!AR:AT,3,FALSE) -> #N/A | H5: =VLOOKUP(A5,TEMP!P:R,3,FALSE) -> #N/A | I5: =VLOOKUP(A5,TEMP!W:Y,3,FALSE) -> #N/A | M5: =VLOOKUP(A5,TEMP!AD:AF,3,FALSE) -> #N/A | Q5: =VLOOKUP(A5,TEMP!AK:AM,3,FALSE) -> #N/A | Y5: =VLOOKUP(A5,TEMP!AY:BA,3,FALSE) -> #N/A | AC5: =VLOOKUP(A5,TEMP!BF:BH,3,FALSE) -> #N/A | AI5: =VLOOKUP(A5,TEMP!B:D,3,FALSE) -> #N/A | BX5: =VLOOKUP(A5,TEMP!BM:BO,3,FALSE) -> #N/A
A6: nusafarma.apotek@gmail.com | B6: base | C6: default | D6: 1 | E6: 1 | F6: =VLOOKUP(A6,TEMP!I:K,3,FALSE) -> #N/A | G6: =VLOOKUP(A6,TEMP!AR:AT,3,FALSE) -> #N/A | H6: =VLOOKUP(A6,TEMP!P:R,3,FALSE) -> #N/A | I6: =VLOOKUP(A6,TEMP!W:Y,3,FALSE) -> #N/A | M6: =VLOOKUP(A6,TEMP!AD:AF,3,FALSE) -> #N/A | Q6: =VLOOKUP(A6,TEMP!AK:AM,3,FALSE) -> #N/A | Y6: =VLOOKUP(A6,TEMP!AY:BA,3,FALSE) -> #N/A | AC6: =VLOOKUP(A6,TEMP!BF:BH,3,FALSE) -> #N/A | AI6: =VLOOKUP(A6,TEMP!B:D,3,FALSE) -> #N/A | BX6: =VLOOKUP(A6,TEMP!BM:BO,3,FALSE) -> #N/A
A7: sekretariat.rsai@gmail.com | B7: base | C7: default | D7: 1 | E7: 1 | F7: =VLOOKUP(A7,TEMP!I:K,3,FALSE) -> #N/A | G7: =VLOOKUP(A7,TEMP!AR:AT,3,FALSE) -> #N/A | H7: =VLOOKUP(A7,TEMP!P:R,3,FALSE) -> #N/A | I7: =VLOOKUP(A7,TEMP!W:Y,3,FALSE) -> #N/A | M7: =VLOOKUP(A7,TEMP!AD:AF,3,FALSE) -> #N/A | Q7: =VLOOKUP(A7,TEMP!AK:AM,3,FALSE) -> #N/A | Y7: =VLOOKUP(A7,TEMP!AY:BA,3,FALSE) -> #N/A | AC7: =VLOOKUP(A7,TEMP!BF:BH,3,FALSE) -> #N/A | AI7: =VLOOKUP(A7,TEMP!B:D,3,FALSE) -> #N/A | BX7: =VLOOKUP(A7,TEMP!BM:BO,3,FALSE) -> #N/A
A8: marketing@edelweiss.id | B8: base | C8: default | D8: 1 | E8: 1 | F8: =VLOOKUP(A8,TEMP!I:K,3,FALSE) -> #N/A | G8: =VLOOKUP(A8,TEMP!AR:AT,3,FALSE) -> #N/A | H8: =VLOOKUP(A8,TEMP!P:R,3,FALSE) -> #N/A | I8: =VLOOKUP(A8,TEMP!W:Y,3,FALSE) -> #N/A | M8: =VLOOKUP(A8,TEMP!AD:AF,3,FALSE) -> #N/A | Q8: =VLOOKUP(A8,TEMP!AK:AM,3,FALSE) -> #N/A | Y8: =VLOOKUP(A8,TEMP!AY:BA,3,FALSE) -> #N/A | AC8: =VLOOKUP(A8,TEMP!BF:BH,3,FALSE) -> #N/A | AI8: =VLOOKUP(A8,TEMP!B:D,3,FALSE) -> #N/A | BX8: =VLOOKUP(A8,TEMP!BM:BO,3,FALSE) -> #N/A
A9: halo@mutiaracikutra.com | B9: base | C9: default | D9: 1 | E9: 1 | F9: =VLOOKUP(A9,TEMP!I:K,3,FALSE) -> #N/A | G9: =VLOOKUP(A9,TEMP!AR:AT,3,FALSE) -> #N/A | H9: =VLOOKUP(A9,TEMP!P:R,3,FALSE) -> #N/A | I9: =VLOOKUP(A9,TEMP!W:Y,3,FALSE) -> #N/A | M9: =VLOOKUP(A9,TEMP!AD:AF,3,FALSE) -> #N/A | Q9: =VLOOKUP(A9,TEMP!AK:AM,3,FALSE) -> #N/A | Y9: =VLOOKUP(A9,TEMP!AY:BA,3,FALSE) -> #N/A | AC9: =VLOOKUP(A9,TEMP!BF:BH,3,FALSE) -> #N/A | AI9: =VLOOKUP(A9,TEMP!B:D,3,FALSE) -> #N/A | BX9: =VLOOKUP(A9,TEMP!BM:BO,3,FALSE) -> #N/A
A10: rspcirebon@rspelabuhan.com | B10: base | C10: default | D10: 1 | E10: 1 | F10: =VLOOKUP(A10,TEMP!I:K,3,FALSE) -> #N/A | G10: =VLOOKUP(A10,TEMP!AR:AT,3,FALSE) -> #N/A | H10: =VLOOKUP(A10,TEMP!P:R,3,FALSE) -> #N/A | I10: =VLOOKUP(A10,TEMP!W:Y,3,FALSE) -> #N/A | M10: =VLOOKUP(A10,TEMP!AD:AF,3,FALSE) -> #N/A | Q10: =VLOOKUP(A10,TEMP!AK:AM,3,FALSE) -> #N/A | Y10: =VLOOKUP(A10,TEMP!AY:BA,3,FALSE) -> #N/A | AC10: =VLOOKUP(A10,TEMP!BF:BH,3,FALSE) -> #N/A | AI10: =VLOOKUP(A10,TEMP!B:D,3,FALSE) -> #N/A | BX10: =VLOOKUP(A10,TEMP!BM:BO,3,FALSE) -> #N/A
A11: sekertariat@rsudbandungkiwari.or.id | B11: base | C11: default | D11: 1 | E11: 1 | F11: =VLOOKUP(A11,TEMP!I:K,3,FALSE) -> #N/A | G11: =VLOOKUP(A11,TEMP!AR:AT,3,FALSE) -> #N/A | H11: =VLOOKUP(A11,TEMP!P:R,3,FALSE) -> #N/A | I11: =VLOOKUP(A11,TEMP!W:Y,3,FALSE) -> #N/A | M11: =VLOOKUP(A11,TEMP!AD:AF,3,FALSE) -> #N/A | Q11: =VLOOKUP(A11,TEMP!AK:AM,3,FALSE) -> #N/A | Y11: =VLOOKUP(A11,TEMP!AY:BA,3,FALSE) -> #N/A | AC11: =VLOOKUP(A11,TEMP!BF:BH,3,FALSE) -> #N/A | AI11: =VLOOKUP(A11,TEMP!B:D,3,FALSE) -> #N/A | BX11: =VLOOKUP(A11,TEMP!BM:BO,3,FALSE) -> #N/A
A12: rantisarnita@yahoo.com | B12: base | C12: default | D12: 1 | E12: 1 | F12: =VLOOKUP(A12,TEMP!I:K,3,FALSE) -> #N/A | G12: =VLOOKUP(A12,TEMP!AR:AT,3,FALSE) -> /legal_documents/company/1520/document_siup.jpeg | H12: =VLOOKUP(A12,TEMP!P:R,3,FALSE) -> /legal_documents/company/1520/document_npwp.jpeg | I12: =VLOOKUP(A12,TEMP!W:Y,3,FALSE) -> #N/A | M12: =VLOOKUP(A12,TEMP!AD:AF,3,FALSE) -> #N/A | Q12: =VLOOKUP(A12,TEMP!AK:AM,3,FALSE) -> /legal_documents/company/1520/document_sipa_sika_apoteker.jpeg | Y12: =VLOOKUP(A12,TEMP!AY:BA,3,FALSE) -> /legal_documents/company/1520/document_stra_apoteker.jpeg | AC12: =VLOOKUP(A12,TEMP!BF:BH,3,FALSE) -> #N/A | AI12: =VLOOKUP(A12,TEMP!B:D,3,FALSE) -> #N/A | BX12: =VLOOKUP(A12,TEMP!BM:BO,3,FALSE) -> /legal_documents/company/1520/document_surat_izin_apotek.jpeg
A13: abufauzan374@gmail.com | B13: base | C13: default | D13: 1 | E13: 1 | F13: =VLOOKUP(A13,TEMP!I:K,3,FALSE) -> #N/A | G13: =VLOOKUP(A13,TEMP!AR:AT,3,FALSE) -> #N/A | H13: =VLOOKUP(A13,TEMP!P:R,3,FALSE) -> #N/A | I13: =VLOOKUP(A13,TEMP!W:Y,3,FALSE) -> #N/A | M13: =VLOOKUP(A13,TEMP!AD:AF,3,FALSE) -> #N/A | Q13: =VLOOKUP(A13,TEMP!AK:AM,3,FALSE) -> #N/A | Y13: =VLOOKUP(A13,TEMP!AY:BA,3,FALSE) -> #N/A | AC13: =VLOOKUP(A13,TEMP!BF:BH,3,FALSE) -> #N/A | AI13: =VLOOKUP(A13,TEMP!B:D,3,FALSE) -> #N/A | BX13: =VLOOKUP(A13,TEMP!BM:BO,3,FALSE) -> #N/A
... A202: uchiharizky2016@gmail.com | B202: base | C202: default | D202: 1 | E202: 1 | F202: =VLOOKUP(A202,TEMP!I:K,3,FALSE) -> #N/A | G202: =VLOOKUP(A202,TEMP!AR:AT,3,FALSE) -> #N/A | H202: =VLOOKUP(A202,TEMP!P:R,3,FALSE) -> #N/A | I202: =VLOOKUP(A202,TEMP!W:Y,3,FALSE) -> #N/A | M202: =VLOOKUP(A202,TEMP!AD:AF,3,FALSE) -> #N/A | Q202: =VLOOKUP(A202,TEMP!AK:AM,3,FALSE) -> #N/A | Y202: =VLOOKUP(A202,TEMP!AY:BA,3,FALSE) -> #N/A | AC202: =VLOOKUP(A202,TEMP!BF:BH,3,FALSE) -> #N/A | AI202: =VLOOKUP(A202,TEMP!B:D,3,FALSE) -> #N/A | BX202: =VLOOKUP(A202,TEMP!BM:BO,3,FALSE) -> #N/A

Sheet TEMP
A1: company_name | B1: Admin_Email | C1: document_name | D1: uploaded_file | E1: expired_date | F1: status | H1: company_name | I1: Admin_Email | J1: document_name | K1: uploaded_file | L1: expired_date | M1: status | O1: company_name | P1: Admin_Email | Q1: document_name | R1: uploaded_file | S1: expired_date | T1: status | V1: company_name | W1: Admin_Email | X1: document_name | Y1: uploaded_file | Z1: expired_date | AA1: status | AC1: company_name | AD1: Admin_Email | AE1: document_name | AF1: uploaded_file | AG1: expired_date | AH1: status | AJ1: company_name | AK1: Admin_Email | AL1: document_name | AM1: uploaded_file | AN1: expired_date | AO1: status | AQ1: company_name | AR1: Admin_Email | AS1: document_name | AT1: uploaded_file | AU1: expired_date | AV1: status | AX1: company_name | AY1: Admin_Email | AZ1: document_name | BA1: uploaded_file | BB1: expired_date | BC1: status | BE1: company_name | BF1: Admin_Email | BG1: document_name | BH1: uploaded_file | BI1: expired_date | BJ1: status | BL1: company_name | BM1: Admin_Email | BN1: document_name | BO1: uploaded_file | BP1: expired_date | BQ1: status
A2: Apotek wijaya kusuma | B2: karsanti1607@gmail.com | C2: document_foto_lokasi_bagunan_fisik | D2: /legal_documents/company/3923/document_foto_lokasi_bagunan_fisik.jpg | F2: pending | H2: hara hita wisesa | I2: muklis32@gmail.com | J2: document_ktp_pemilik_sarana | K2: /legal_documents/company/34577/document_ktp_pemilik_sarana.jpeg | M2: pending | O2: PKU MUHAMMADIYAH SRUWENG | P2: pkumuhsruweng1@gmail.com | Q2: document_npwp | R2: /legal_documents/company/2745/document_npwp.jpeg | T2: pending | V2: Bima Sakti medica | W2: ptbimasaktimedicamb1@gmail.com | X2: document_sertifikasi_cdob | Y2: /legal_documents/company/3895/document_sertifikasi_cdob.jpeg | Z2: 45603 | AA2: pending | AC2: PT. Lamlo Pharmacy | AD2: lamlopharmacypt@yahoo.com | AE2: document_sertifikat_cdakb | AF2: /legal_documents/company/3142/document_sertifikat_cdakb.jpeg | AG2: 45420 | AH2: pending | AJ2: Apotik Bahagia | AK2: arie_4121mel@yahoo.com | AL2: document_sipa_sika_apoteker | AM2: /legal_documents/company/3921/document_sipa_sika_apoteker.jpg | AO2: pending | AQ2: Apotik Bahagia | AR2: arie_4121mel@yahoo.com | AS2: document_siup | AT2: /legal_documents/company/3921/document_siup.pdf | AV2: pending | AX2: PKU MUHAMMADIYAH SRUWENG | AY2: pkumuhsruweng1@gmail.com | AZ2: document_stra_apoteker | BA2: /legal_documents/company/2745/document_stra_apoteker.jpeg | BB2: 46024 | BC2: pending | BE2: Toko Obat Aneka Jaya | BF2: anekajayamartoloyo@gmail.com | BG2: document_strttk | BH2: /legal_documents/company/2591/document_strttk.pdf | BI2: 46617 | BJ2: pending | BL2: Apotek wijaya kusuma | BM2: karsanti1607@gmail.com | BN2: document_surat_izin_apotek | BO2: /legal_documents/company/3923/document_surat_izin_apotek.jpg | BP2: 45681 | BQ2: pending
A3: RSU PURBOWANGI | B3: rsupurbowangigmb@gmail.com | C3: document_foto_lokasi_bagunan_fisik | D3: /legal_documents/company/3754/document_foto_lokasi_bagunan_fisik.pdf | F3: pending | H3: Apotek Sedulur | I3: antoniraharjo115@gmail.com | J3: document_ktp_pemilik_sarana | K3: /legal_documents/company/20826/document_ktp_pemilik_sarana.jpeg | M3: pending | O3: Apotek wijaya kusuma | P3: karsanti1607@gmail.com | Q3: document_npwp | R3: /legal_documents/company/3923/document_npwp.jpg | T3: pending | V3: PT Citra Sedayuh | W3: citrasedayuh@gmail.com | X3: document_sertifikasi_cdob | Y3: /legal_documents/company/4032/document_sertifikasi_cdob.pdf | Z3: 45408 | AA3: pending | AC3: PT. Sejahtera Harapan Tigas | AD3: pbf.sehati@gmail.com | AE3: document_sertifikat_cdakb | AF3: /legal_documents/company/4725/document_sertifikat_cdakb.pdf | AG3: 46116 | AH3: pending | AJ3: PKU MUHAMMADIYAH SRUWENG | AK3: pkumuhsruweng1@gmail.com | AL3: document_sipa_sika_apoteker | AM3: /legal_documents/company/2745/document_sipa_sika_apoteker.jpeg | AN3: 46024 | AO3: pending | AQ3: PKU MUHAMMADIYAH SRUWENG | AR3: pkumuhsruweng1@gmail.com | AS3: document_siup | AT3: /legal_documents/company/2745/document_siup.png | AU3: 46024 | AV3: pending | AX3: Apotek Mitra Sehat Farma | AY3: yuniatianes@gmail.com | AZ3: document_stra_apoteker | BA3: /legal_documents/company/3919/document_stra_apoteker.pdf | BB3: 46567 | BC3: pending | BE3: PT. KIMIA FARMA TRADING AND DISTRIBUTION | BF3: KFTDMALANG@YAHOO.CO.ID | BG3: document_strttk | BH3: /legal_documents/company/4357/document_strttk.jpeg | BI3: 46076 | BJ3: pending | BL3: Apotek Mitra Sehat Farma | BM3: yuniatianes@gmail.com | BN3: document_surat_izin_apotek | BO3: /legal_documents/company/3919/document_surat_izin_apotek.pdf | BP3: 47663 | BQ3: pending
A4: Apotek Mutiara Farma | B4: aptmutiarafarma1@gmail.com | C4: document_foto_lokasi_bagunan_fisik | D4: /legal_documents/company/3926/document_foto_lokasi_bagunan_fisik.jpeg | F4: pending | H4: Apotek Testing | I4: medbizkftd+12345678@gmail.com | J4: document_ktp_pemilik_sarana | K4: /legal_documents/company/34579/document_ktp_pemilik_sarana.pdf | M4: pending | O4: RSU PURBOWANGI | P4: rsupurbowangigmb@gmail.com | Q4: document_npwp | R4: /legal_documents/company/3754/document_npwp.jpeg | T4: pending | V4: PT. Forta Mitra Sejati | W4: apjforta@gmail.com | X4: document_sertifikasi_cdob | Y4: /legal_documents/company/2972/document_sertifikasi_cdob.PDF | Z4: 45842 | AA4: pending | AC4: PT Teluk Pursel Sejahtera | AD4: telukpurselpurwokerto@gmail.com | AE4: document_sertifikat_cdakb | AF4: /legal_documents/company/4913/document_sertifikat_cdakb.pdf | AG4: 46548 | AH4: pending | AJ4: Apotek wijaya kusuma | AK4: karsanti1607@gmail.com | AL4: document_sipa_sika_apoteker | AM4: /legal_documents/company/3923/document_sipa_sika_apoteker.jpg | AN4: 45681 | AO4: pending | AQ4: Apotek wijaya kusuma | AR4: karsanti1607@gmail.com | AS4: document_siup | AT4: /legal_documents/company/3923/document_siup.jpg | AU4: 45880 | AV4: pending | AX4: Apotek Mutiara Farma | AY4: aptmutiarafarma1@gmail.com | AZ4: document_stra_apoteker | BA4: /legal_documents/company/3926/document_stra_apoteker.jpeg | BB4: 46113 | BC4: pending | BE4: PT. Lamlo Pharmacy | BF4: lamlopharmacypt@yahoo.com | BG4: document_strttk | BH4: /legal_documents/company/3142/document_strttk.jpeg | BI4: 45506 | BJ4: pending | BL4: Apotek Mutiara Farma | BM4: aptmutiarafarma1@gmail.com | BN4: document_surat_izin_apotek | BO4: /legal_documents/company/3926/document_surat_izin_apotek.jpeg | BP4: 46113 | BQ4: pending
A5: RS EMANUEL BANJARNEGARA | B5: rs.emanuelbna@gmail.com | C5: document_foto_lokasi_bagunan_fisik | D5: /legal_documents/company/1999/document_foto_lokasi_bagunan_fisik.png | F5: pending | H5: PT ADI BUANA CITRA DHARMALA | I5: medbizkftd+10012020@gmail.com | J5: document_ktp_pemilik_sarana | K5: /legal_documents/company/27230/document_ktp_pemilik_sarana.pdf | M5: pending | O5: Apotek Mitra Sehat Farma | P5: yuniatianes@gmail.com | Q5: document_npwp | R5: /legal_documents/company/3919/document_npwp.pdf | T5: pending | V5: PT. Sinar Roda Utama | W5: evelyn.n@sinarrodautama.co.id | X5: document_sertifikasi_cdob | Y5: /legal_documents/company/1922/document_sertifikasi_cdob.PDF | Z5: 46035 | AA5: pending | AC5: PT Pancabala Jaya Makmur | AD5: ptpancabalajayamakmur@gmail.com | AE5: document_sertifikat_cdakb | AF5: /legal_documents/company/1917/document_sertifikat_cdakb.jpg | AG5: 45586 | AH5: pending | AJ5: Apotek Mitra Sehat Farma | AK5: yuniatianes@gmail.com | AL5: document_sipa_sika_apoteker | AM5: /legal_documents/company/3919/document_sipa_sika_apoteker.pdf | AN5: 46567 | AO5: pending | AQ5: RSU PURBOWANGI | AR5: rsupurbowangigmb@gmail.com | AS5: document_siup | AT5: /legal_documents/company/3754/document_siup.pdf | AU5: 46470 | AV5: pending | AX5: Apotek wijaya kusuma | AY5: karsanti1607@gmail.com | AZ5: document_stra_apoteker | BA5: /legal_documents/company/3923/document_stra_apoteker.jpg | BB5: 45681 | BC5: pending | BE5: PT. Rajawali Nusindo Cabang Padang | BF5: rnimedbiz@gmail.com | BG5: document_strttk | BH5: /legal_documents/company/4828/document_strttk.jpg | BI5: 46557 | BJ5: pending | BL5: APT. ADHI GUNA FARMA | BM5: adhigunafarma.01@gmail.com | BN5: document_surat_izin_apotek | BO5: /legal_documents/company/2717/document_surat_izin_apotek.jpg | BP5: 46537 | BQ5: pending
A6: Apotek Irawan Medika | B6: apotekirawanmedikamb1@gmail.com | C6: document_foto_lokasi_bagunan_fisik | D6: /legal_documents/company/3990/document_foto_lokasi_bagunan_fisik.jpeg | F6: pending | H6: Apotek Faiza | I6: setyanuria@gmail.com | J6: document_ktp_pemilik_sarana | K6: /legal_documents/company/20500/document_ktp_pemilik_sarana.jpeg | M6: pending | O6: Apotek Mutiara Farma | P6: aptmutiarafarma1@gmail.com | Q6: document_npwp | R6: /legal_documents/company/3926/document_npwp.jpeg | T6: pending | V6: PT. ANTAR MITRA PAPUA | W6: ampjayapura@yahoo.com | X6: document_sertifikasi_cdob | Y6: /legal_documents/company/4220/document_sertifikasi_cdob.PDF | Z6: 45719 | AA6: pending | AC6: PT Berkat Mahkota Putra | AD6: ptberkatmahkotaputra@gmail.com | AE6: document_sertifikat_cdakb | AF6: /legal_documents/company/1915/document_sertifikat_cdakb.pdf | AG6: 46235 | AH6: pending | AJ6: Apotek Mutiara Farma | AK6: aptmutiarafarma1@gmail.com | AL6: document_sipa_sika_apoteker | AM6: /legal_documents/company/3926/document_sipa_sika_apoteker.jpeg | AN6: 46113 | AO6: pending | AQ6: Apotek Mitra Sehat Farma | AR6: yuniatianes@gmail.com | AS6: document_siup | AT6: /legal_documents/company/3919/document_siup.pdf | AU6: 45291 | AV6: pending | AX6: APT. ADHI GUNA FARMA | AY6: adhigunafarma.01@gmail.com | AZ6: document_stra_apoteker | BA6: /legal_documents/company/2717/document_stra_apoteker.jpg | BB6: 46537 | BC6: pending | BE6: PT Teluk Pursel Sejahtera | BF6: telukpurselpurwokerto@gmail.com | BG6: document_strttk | BH6: /legal_documents/company/4913/document_strttk.pdf | BI6: 46329 | BJ6: pending | BL6: Apotek Rawa Bendungan | BM6: febianamelisa123@gmail.com | BN6: document_surat_izin_apotek | BO6: /legal_documents/company/1622/document_surat_izin_apotek.pdf | BP6: 46055 | BQ6: pending
A7: Apotek Pratama K2 | B7: apotekpratamak2mb1@gmail.com | C7: document_foto_lokasi_bagunan_fisik | D7: /legal_documents/company/3991/document_foto_lokasi_bagunan_fisik.jpeg | F7: pending | H7: APOTEK ACHA FARMA | I7: medbizkftd+10077803@gmail.com | J7: document_ktp_pemilik_sarana | K7: /legal_documents/company/7401/document_ktp_pemilik_sarana.png | M7: pending | O7: RS EMANUEL BANJARNEGARA | P7: rs.emanuelbna@gmail.com | Q7: document_npwp | R7: /legal_documents/company/1999/document_npwp.jpeg | T7: pending | V7: PT. KA DUA EMPAT | W7: ibrahimmalik504@gmail.com | X7: document_sertifikasi_cdob | Y7: /legal_documents/company/4268/document_sertifikasi_cdob.pdf | Z7: 46695 | AA7: pending | AC7: PT. MITRA KELUARGA MANDIRI PAPUA | AD7: eko@mkmp.co.id | AE7: document_sertifikat_cdakb | AF7: /legal_documents/company/3749/document_sertifikat_cdakb.pdf | AG7: 45509 | AH7: pending | AJ7: APT. ADHI GUNA FARMA | AK7: adhigunafarma.01@gmail.com | AL7: document_sipa_sika_apoteker | AM7: /legal_documents/company/2717/document_sipa_sika_apoteker.jpg | AN7: 46537 | AO7: pending | AQ7: Apotek Mutiara Farma | AR7: aptmutiarafarma1@gmail.com | AS7: document_siup | AT7: /legal_documents/company/3926/document_siup.jpeg | AU7: 46113 | AV7: pending | AX7: RS EMANUEL BANJARNEGARA | AY7: rs.emanuelbna@gmail.com | AZ7: document_stra_apoteker | BA7: /legal_documents/company/1999/document_stra_apoteker.jpeg | BB7: 46318 | BC7: pending | BE7: Toko Obat Adek Padang | BF7: toadekpdg@gmail.com | BG7: document_strttk | BH7: /legal_documents/company/5007/document_strttk.pdf | BI7: 46149 | BJ7: pending | BL7: Apotek Irawan Medika | BM7: apotekirawanmedikamb1@gmail.com | BN7: document_surat_izin_apotek | BO7: /legal_documents/company/3990/document_surat_izin_apotek.jpeg | BP7: 45780 | BQ7: pending
A8: apotek Mata Merah | B8: apotekmatamerahmb1@gmail.com | C8: document_foto_lokasi_bagunan_fisik | D8: /legal_documents/company/3992/document_foto_lokasi_bagunan_fisik.pdf | F8: pending | H8: RSU. PROF ALOEI SABOE | I8: medbizkftd+10006176@gmail.com | J8: document_ktp_pemilik_sarana | K8: /legal_documents/company/8766/document_ktp_pemilik_sarana.jpeg | M8: pending | O8: Apotek Rawa Bendungan | P8: febianamelisa123@gmail.com | Q8: document_npwp | R8: /legal_documents/company/1622/document_npwp.pdf | T8: pending | V8: PT. Sumber Agung Sentosa | W8: ptsas.mail@gmail.com | X8: document_sertifikasi_cdob | Y8: /legal_documents/company/4292/document_sertifikasi_cdob.pdf | Z8: 45654 | AA8: pending | AC8: PT. Omega Medika Gemilang | AD8: omegamedikagemilang123@gmail.com | AE8: document_sertifikat_cdakb | AF8: /legal_documents/company/2212/document_sertifikat_cdakb.jpeg | AG8: 46598 | AH8: pending | AJ8: RS EMANUEL BANJARNEGARA | AK8: rs.emanuelbna@gmail.com | AL8: document_sipa_sika_apoteker | AM8: /legal_documents/company/1999/document_sipa_sika_apoteker.jpeg | AN8: 46318 | AO8: pending | AQ8: APT. ADHI GUNA FARMA | AR8: adhigunafarma.01@gmail.com | AS8: document_siup | AT8: /legal_documents/company/2717/document_siup.pdf | AU8: 46537 | AV8: pending | AX8: Apotek Rawa Bendungan | AY8: febianamelisa123@gmail.com | AZ8: document_stra_apoteker | BA8: /legal_documents/company/1622/document_stra_apoteker.pdf | BB8: 46055 | BC8: pending | BE8: PT Pancabala Jaya Makmur | BF8: ptpancabalajayamakmur@gmail.com | BG8: document_strttk | BH8: /legal_documents/company/1917/document_strttk.jpg | BI8: 46195 | BJ8: pending | BL8: Apotek Pratama K2 | BM8: apotekpratamak2mb1@gmail.com | BN8: document_surat_izin_apotek | BO8: /legal_documents/company/3991/document_surat_izin_apotek.jpeg | BP8: 46023 | BQ8: pending
A9: Apotek Simpang Limo | B9: apoteksimpanglimomb1@gmail.com | C9: document_foto_lokasi_bagunan_fisik | D9: /legal_documents/company/3993/document_foto_lokasi_bagunan_fisik.jpeg | F9: pending | H9: Apotek Sulthan | I9: rinhope2023@gmail.com | J9: document_ktp_pemilik_sarana | K9: /legal_documents/company/34585/document_ktp_pemilik_sarana.jpeg | M9: pending | O9: Apotek Irawan Medika | P9: apotekirawanmedikamb1@gmail.com | Q9: document_npwp | R9: /legal_documents/company/3990/document_npwp.jpeg | T9: pending | V9: PT Karunia Mitra Distribusi | W9: ptkaruniamitradistribusimb1@gmail.com | X9: document_sertifikasi_cdob | Y9: /legal_documents/company/3998/document_sertifikasi_cdob.pdf | Z9: 45329 | AA9: pending | AC9: PT. Bintang Timur Husada | AD9: pt.bthpapua@gmail.com | AE9: document_sertifikat_cdakb | AF9: /legal_documents/company/5050/document_sertifikat_cdakb.pdf | AG9: 45909 | AH9: pending | AJ9: Apotek Rawa Bendungan | AK9: febianamelisa123@gmail.com | AL9: document_sipa_sika_apoteker | AM9: /legal_documents/company/1622/document_sipa_sika_apoteker.pdf | AN9: 46055 | AO9: pending | AQ9: RS EMANUEL BANJARNEGARA | AR9: rs.emanuelbna@gmail.com | AS9: document_siup | AT9: /legal_documents/company/1999/document_siup.png | AU9: 45398 | AV9: pending | AX9: Apotek Irawan Medika | AY9: apotekirawanmedikamb1@gmail.com | AZ9: document_stra_apoteker | BA9: /legal_documents/company/3990/document_stra_apoteker.jpeg | BB9: 45780 | BC9: pending | BE9: PT Berkat Mahkota Putra | BF9: ptberkatmahkotaputra@gmail.com | BG9: document_strttk | BH9: /legal_documents/company/1915/document_strttk.pdf | BI9: 46235 | BJ9: pending | BL9: Bima Sakti medica | BM9: ptbimasaktimedicamb1@gmail.com | BN9: document_surat_izin_pbf | BO9: /legal_documents/company/3895/document_surat_izin_pbf.jpeg | BP9: 45210 | BQ9: pending
A10: Apotek Refah | B10: apotekrefahmb1@gmail.com | C10: document_foto_lokasi_bagunan_fisik | D10: /legal_documents/company/3994/document_foto_lokasi_bagunan_fisik.jpeg | F10: pending | H10: APOTEK AL-ZAHRAWI | I10: apotekalzahrawi@gmail.com | J10: document_ktp_pemilik_sarana | K10: /legal_documents/company/34587/document_ktp_pemilik_sarana.jpeg | M10: pending | O10: Apotek Pratama K2 | P10: apotekpratamak2mb1@gmail.com | Q10: document_npwp | R10: /legal_documents/company/3991/document_npwp.jpeg | T10: pending | V10: PT Millenia Dharma Insani | W10: ptmilleniadharmainsani@gmail.com | X10: document_sertifikasi_cdob | Y10: /legal_documents/company/4348/document_sertifikasi_cdob.pdf | Z10: 45518 | AA10: pending | AC10: PT. Sakyo Putra Pratama | AD10: putrasakyo@gmail.com | AE10: document_sertifikat_cdakb | AF10: /legal_documents/company/1964/document_sertifikat_cdakb.PDF | AG10: 45807 | AH10: pending | AJ10: Apotek Irawan Medika | AK10: apotekirawanmedikamb1@gmail.com | AL10: document_sipa_sika_apoteker | AM10: /legal_documents/company/3990/document_sipa_sika_apoteker.jpeg | AN10: 45780 | AO10: pending | AQ10: Apotek Rawa Bendungan | AR10: febianamelisa123@gmail.com | AS10: document_siup | AT10: /legal_documents/company/1622/document_siup.pdf | AU10: 46055 | AV10: pending | AX10: Apotek Pratama K2 | AY10: apotekpratamak2mb1@gmail.com | AZ10: document_stra_apoteker | BA10: /legal_documents/company/3991/document_stra_apoteker.jpeg | BB10: 46382 | BC10: pending | BE10: PT. MITRA KELUARGA MANDIRI PAPUA | BF10: eko@mkmp.co.id | BG10: document_strttk | BH10: /legal_documents/company/3749/document_strttk.pdf | BI10: 45509 | BJ10: pending | BL10: apotek Mata Merah | BM10: apotekmatamerahmb1@gmail.com | BN10: document_surat_izin_apotek | BO10: /legal_documents/company/3992/document_surat_izin_apotek.pdf | BP10: 46637 | BQ10: pending
A11: RS. PMI BOGOR | B11: rspmibogor123@gmail.com | C11: document_foto_lokasi_bagunan_fisik | D11: /legal_documents/company/2145/document_foto_lokasi_bagunan_fisik.pdf | F11: pending | H11: APOTEK KUSUMA FARMA | I11: inggritharoa10@gmail.com | J11: document_ktp_pemilik_sarana | K11: /legal_documents/company/5173/document_ktp_pemilik_sarana.jpeg | M11: pending | O11: Bima Sakti medica | P11: ptbimasaktimedicamb1@gmail.com | Q11: document_npwp | R11: /legal_documents/company/3895/document_npwp.jpeg | T11: pending | V11: PT. PAPUA SUKSES ABADI | W11: papua.sukses.abadi@gmail.com | X11: document_sertifikasi_cdob | Y11: /legal_documents/company/4307/document_sertifikasi_cdob.PDF | Z11: 45883 | AA11: pending | AC11: PT. Medimart Mega Rezeki | AD11: medimartmegarezeki123@gmail.com | AE11: document_sertifikat_cdakb | AF11: /legal_documents/company/3324/document_sertifikat_cdakb.pdf | AG11: 46580 | AH11: pending | AJ11: Apotek Pratama K2 | AK11: apotekpratamak2mb1@gmail.com | AL11: document_sipa_sika_apoteker | AM11: /legal_documents/company/3991/document_sipa_sika_apoteker.jpeg | AN11: 46382 | AO11: pending | AQ11: Apotek Irawan Medika | AR11: apotekirawanmedikamb1@gmail.com | AS11: document_siup | AT11: /legal_documents/company/3990/document_siup.jpeg | AU11: 45780 | AV11: pending | AX11: Bima Sakti medica | AY11: ptbimasaktimedicamb1@gmail.com | AZ11: document_stra_apoteker | BA11: /legal_documents/company/3895/document_stra_apoteker.jpeg | BB11: 45520 | BC11: pending | BE11: PT. Omega Medika Gemilang | BF11: omegamedikagemilang123@gmail.com | BG11: document_strttk | BH11: /legal_documents/company/2212/document_strttk.jpeg | BI11: 46023 | BJ11: pending | BL11: Apotek Simpang Limo | BM11: apoteksimpanglimomb1@gmail.com | BN11: document_surat_izin_apotek | BO11: /legal_documents/company/3993/document_surat_izin_apotek.jpeg | BP11: 46160 | BQ11: pending
A12: APT. DUNIA SEHAT I | B12: elliyusnimar66@gmail.com | C12: document_foto_lokasi_bagunan_fisik | D12: /legal_documents/company/3737/document_foto_lokasi_bagunan_fisik.jpg | F12: pending | H12: apotek ibrarfarma 09 | I12: apotekibrarfarma09@gmail.com | J12: document_ktp_pemilik_sarana | K12: /legal_documents/company/34589/document_ktp_pemilik_sarana.jpeg | M12: pending | O12: apotek Mata Merah | P12: apotekmatamerahmb1@gmail.com | Q12: document_npwp | R12: /legal_documents/company/3992/document_npwp.pdf | T12: pending | V12: PT. KIMIA FARMA TRADING AND DISTRIBUTION | W12: KFTDMALANG@YAHOO.CO.ID | X12: document_sertifikasi_cdob | Y12: /legal_documents/company/4357/document_sertifikasi_cdob.pdf | Z12: 46670 | AA12: pending | AC12: PT. Matahari Utama Sehat | AD12: Apotekerrenny@gmail.com | AE12: document_sertifikat_cdakb | AF12: /legal_documents/company/3752/document_sertifikat_cdakb.pdf | AG12: 45883 | AH12: pending | AJ12: Bima Sakti medica | AK12: ptbimasaktimedicamb1@gmail.com | AL12: document_sipa_sika_apoteker | AM12: /legal_documents/company/3895/document_sipa_sika_apoteker.jpeg | AN12: 45520 | AO12: pending | AQ12: Apotek Pratama K2 | AR12: apotekpratamak2mb1@gmail.com | AS12: document_siup | AT12: /legal_documents/company/3991/document_siup.jpeg | AU12: 46370 | AV12: pending | AX12: apotek Mata Merah | AY12: apotekmatamerahmb1@gmail.com | AZ12: document_stra_apoteker | BA12: /legal_documents/company/3992/document_stra_apoteker.pdf | BB12: 46637 | BC12: pending | BE12: PT. Bintang Timur Husada | BF12: pt.bthpapua@gmail.com | BG12: document_strttk | BH12: /legal_documents/company/5050/document_strttk.pdf | BI12: 45909 | BJ12: pending | BL12: Apotek Refah | BM12: apotekrefahmb1@gmail.com | BN12: document_surat_izin_apotek | BO12: /legal_documents/company/3994/document_surat_izin_apotek.jpeg | BP12: 46394 | BQ12: pending
A13: Apotik Berkat | B13: amar160721@gmail.com | C13: document_foto_lokasi_bagunan_fisik | D13: /legal_documents/company/3925/document_foto_lokasi_bagunan_fisik.jpg | F13: pending | H13: Apotek Bonang Farma | I13: muzamil050574@gmail.com | J13: document_ktp_pemilik_sarana | K13: /legal_documents/company/4747/document_ktp_pemilik_sarana.pdf | M13: pending | O13: Apotek Simpang Limo | P13: apoteksimpanglimomb1@gmail.com | Q13: document_npwp | R13: /legal_documents/company/3993/document_npwp.jpeg | T13: pending | V13: PT. Rinjani Farma | W13: ptrinjanifarma@gmail.com | X13: document_sertifikasi_cdob | Y13: /legal_documents/company/4369/document_sertifikasi_cdob.pdf | Z13: 45965 | AA13: pending | AC13: PT. MUTIARA MAJU MANDIRI | AD13: mutiaramajumandiript@gmail.com | AE13: document_sertifikat_cdakb | AF13: /legal_documents/company/1990/document_sertifikat_cdakb.jpg | AG13: 46097 | AH13: pending | AJ13: apotek Mata Merah | AK13: apotekmatamerahmb1@gmail.com | AL13: document_sipa_sika_apoteker | AM13: /legal_documents/company/3992/document_sipa_sika_apoteker.pdf | AN13: 46637 | AO13: pending | AQ13: Bima Sakti medica | AR13: ptbimasaktimedicamb1@gmail.com | AS13: document_siup | AT13: /legal_documents/company/3895/document_siup.jpeg | AU13: 47099 | AV13: pending | AX13: Apotek Simpang Limo | AY13: apoteksimpanglimomb1@gmail.com | AZ13: document_stra_apoteker | BA13: /legal_documents/company/3993/document_stra_apoteker.jpeg | BB13: 46297 | BC13: pending | BE13: PT. Sakyo Putra Pratama | BF13: putrasakyo@gmail.com | BG13: document_strttk | BH13: /legal_documents/company/1964/document_strttk.pdf | BI13: 46459 | BJ13: pending | BL13: Apotik Mahameru | BM13: apotikmahameru@gmail.com | BN13: document_surat_izin_apotek | BO13: /legal_documents/company/3995/document_surat_izin_apotek.jpeg | BP13: 45855 | BQ13: pending
A14: APT. KRAJAN FARMA KRIAN | B14: apotekkrajan@gmail.com | C14: document_foto_lokasi_bagunan_fisik | D14: /legal_documents/company/3945/document_foto_lokasi_bagunan_fisik.jpg | F14: pending | H14: Apotek Pajampangan | I14: muhamaddawilafkar21@gmail.com | J14: document_ktp_pemilik_sarana | K14: /legal_documents/company/34591/document_ktp_pemilik_sarana.pdf | M14: pending | O14: Apotek Refah | P14: apotekrefahmb1@gmail.com | Q14: document_npwp | R14: /legal_documents/company/3994/document_npwp.jpeg | T14: pending | V14: PT Aman Farmasindo Abadi | W14: 79suhendra@gmail.com | X14: document_sertifikasi_cdob | Y14: /legal_documents/company/2954/document_sertifikasi_cdob.PDF | Z14: 46268 | AA14: pending | AC14: PT. Sinar Bintang Papua | AD14: sinarbintangpapua88@gmail.com | AE14: document_sertifikat_cdakb | AF14: /legal_documents/company/5126/document_sertifikat_cdakb.pdf | AG14: 45955 | AH14: pending | AJ14: Apotek Simpang Limo | AK14: apoteksimpanglimomb1@gmail.com | AL14: document_sipa_sika_apoteker | AM14: /legal_documents/company/3993/document_sipa_sika_apoteker.jpeg | AN14: 46224 | AO14: pending | AQ14: apotek Mata Merah | AR14: apotekmatamerahmb1@gmail.com | AS14: document_siup | AT14: /legal_documents/company/3992/document_siup.pdf | AU14: 46637 | AV14: pending | AX14: Apotek Refah | AY14: apotekrefahmb1@gmail.com | AZ14: document_stra_apoteker | BA14: /legal_documents/company/3994/document_stra_apoteker.jpeg | BB14: 46394 | BC14: pending | BE14: PT. Medimart Mega Rezeki | BF14: medimartmegarezeki123@gmail.com | BG14: document_strttk | BH14: /legal_documents/company/3324/document_strttk.pdf | BI14: 46054 | BJ14: pending | BL14: APT. VILLY FARMA 2 | BM14: Villyfarma2@gmail.com | BN14: document_surat_izin_apotek | BO14: /legal_documents/company/3922/document_surat_izin_apotek.jpeg | BP14: 46265 | BQ14: pending
... A21: APT. PRAYOGI | B21: widjajaprayogi@gmail.com | C21: document_foto_lokasi_bagunan_fisik | D21: /legal_documents/company/2344/document_foto_lokasi_bagunan_fisik.jpg | F21: pending | H21: APOTEK GEMA SEHAT | I21: PUTRI.SOLIRA@GMAIL.COM | J21: document_ktp_pemilik_sarana | K21: /legal_documents/company/22786/document_ktp_pemilik_sarana.jpeg | M21: pending | O21: APT. SEJAHTERA MEDIKA BANGKALAN | P21: aptmuthmainnah@gmail.com | Q21: document_npwp | R21: /legal_documents/company/3458/document_npwp.jpeg | T21: pending | V21: PT. Gelora Fajar Farma | W21: gelora.fajar@yahoo.com | X21: document_sertifikasi_cdob | Y21: /legal_documents/company/4629/document_sertifikasi_cdob.pdf | Z21: 45628 | AA21: pending | AC21: PT. FEGRAMAX MITRA MANDIRI | AD21: fegramaxmitramandiri@gmail.com | AE21: document_sertifikat_cdakb | AF21: /legal_documents/company/6275/document_sertifikat_cdakb.pdf | AG21: 45541 | AH21: pending | AJ21: RS. PMI BOGOR | AK21: rspmibogor123@gmail.com | AL21: document_sipa_sika_apoteker | AM21: /legal_documents/company/2145/document_sipa_sika_apoteker.pdf | AN21: 47483 | AO21: pending | AQ21: RS. PMI BOGOR | AR21: rspmibogor123@gmail.com | AS21: document_siup | AT21: /legal_documents/company/2145/document_siup.pdf | AU21: 46387 | AV21: pending | AX21: APT. DUNIA SEHAT I | AY21: elliyusnimar66@gmail.com | AZ21: document_stra_apoteker | BA21: /legal_documents/company/3737/document_stra_apoteker.pdf | BB21: 46038 | BC21: pending | BE21: PT. Utama Binafarma | BF21: pt.utama.binafarma.order@gmail.com | BG21: document_strttk | BH21: /legal_documents/company/5432/document_strttk.jpg | BI21: 44983 | BJ21: pending | BL21: Apotek Yani baru | BM21: yanibaru07@gmail.com | BN21: document_surat_izin_apotek | BO21: /legal_documents/company/3892/document_surat_izin_apotek.pdf | BP21: 46032 | BQ21: pending
A22: Apotek Kulon Palang | B22: kulonpalang47@gmail.com | C22: document_foto_lokasi_bagunan_fisik | D22: /legal_documents/company/3797/document_foto_lokasi_bagunan_fisik.pdf | F22: pending | H22: Apotek kreweng | I22: apoteksmkreweng@gmail.com | J22: document_ktp_pemilik_sarana | K22: /legal_documents/company/1614/document_ktp_pemilik_sarana.jpeg | M22: pending | O22: APT. DUNIA SEHAT I | P22: elliyusnimar66@gmail.com | Q22: document_npwp | R22: /legal_documents/company/3737/document_npwp.jpg | T22: pending | V22: PT. Graha Sejati Medika | W22: Gsmgrahasejati@gmail.com | X22: document_sertifikasi_cdob | Y22: /legal_documents/company/4718/document_sertifikasi_cdob.pdf | Z22: 45576 | AA22: pending | AC22: PT. BUNDA GLOBAL PHARMA | AD22: drafdi@gmail.com | AE22: document_sertifikat_cdakb | AF22: /legal_documents/company/6272/document_sertifikat_cdakb.pdf | AG22: 46275 | AH22: pending | AJ22: APT. SEJAHTERA MEDIKA BANGKALAN | AK22: aptmuthmainnah@gmail.com | AL22: document_sipa_sika_apoteker | AM22: /legal_documents/company/3458/document_sipa_sika_apoteker.jpeg | AN22: 45806 | AO22: pending | AQ22: APT. DUNIA SEHAT I | AR22: elliyusnimar66@gmail.com | AS22: document_siup | AT22: /legal_documents/company/3737/document_siup.pdf | AU22: 46038 | AV22: pending | AX22: Apotik winning | AY22: apotikwinning@gmail.com | AZ22: document_stra_apoteker | BA22: /legal_documents/company/3996/document_stra_apoteker.jpeg | BB22: 46502 | BC22: pending | BE22: Toko Obat Mama En | BF22: tomama.en@gmail.com | BG22: document_strttk | BH22: /legal_documents/company/5669/document_strttk.pdf | BJ22: pending | BL22: APT. MONICA | BM22: aptmonica96@gmail.com | BN22: document_surat_izin_apotek | BO22: /legal_documents/company/4002/document_surat_izin_apotek.pdf | BP22: 46052 | BQ22: pending
A23: RSU ANNIMAH | B23: annimahrsu@gmail.com | C23: document_foto_lokasi_bagunan_fisik | D23: /legal_documents/company/4057/document_foto_lokasi_bagunan_fisik.pdf | F23: pending | H23: APOTEK ADIRO | I23: adiropharmacy@gmail.com | J23: document_ktp_pemilik_sarana | K23: /legal_documents/company/20636/document_ktp_pemilik_sarana.jpeg | M23: pending | O23: RSUD Lubuk Sikaping | P23: rsudlubuksikaping1@gmail.com | Q23: document_npwp | R23: /legal_documents/company/3997/document_npwp.pdf | T23: pending | V23: PT. Nusa Jaya Raya | W23: nusajayarayapt@gmail.com | X23: document_sertifikasi_cdob | Y23: /legal_documents/company/4727/document_sertifikasi_cdob.pdf | Z23: 45214 | AA23: pending | AC23: PT LOGIN SUKSES | AD23: sukses.login@yahoo.co.id | AE23: document_sertifikat_cdakb | AF23: /legal_documents/company/3251/document_sertifikat_cdakb.pdf | AH23: pending | AJ23: APT. DUNIA SEHAT I | AK23: elliyusnimar66@gmail.com | AL23: document_sipa_sika_apoteker | AM23: /legal_documents/company/3737/document_sipa_sika_apoteker.pdf | AN23: 46038 | AO23: pending | AQ23: APT. SEJAHTERA MEDIKA BANGKALAN | AR23: aptmuthmainnah@gmail.com | AS23: document_siup | AT23: /legal_documents/company/3458/document_siup.jpeg | AU23: 46536 | AV23: pending | AX23: RSUD Lubuk Sikaping | AY23: rsudlubuksikaping1@gmail.com | AZ23: document_stra_apoteker | BA23: /legal_documents/company/3997/document_stra_apoteker.pdf | BB23: 46091 | BC23: pending | BE23: PT. Adi Pratama Farma | BF23: apf.medbiz@gmail.com | BG23: document_strttk | BH23: /legal_documents/company/5748/document_strttk.jpeg | BI23: 46175 | BJ23: pending | BL23: Apotik Berkat | BM23: amar160721@gmail.com | BN23: document_surat_izin_apotek | BO23: /legal_documents/company/3925/document_surat_izin_apotek.jpg | BP23: 46299 | BQ23: pending
A24: Rumah Sakit Mardi Rahayu | B24: pembelianmedis@gmail.com | C24: document_foto_lokasi_bagunan_fisik | D24: /legal_documents/company/2348/document_foto_lokasi_bagunan_fisik.jpg | F24: pending | H24: KLINIK PERSADA MEDICAL | I24: apotekpersadamedical@gmail.com | J24: document_ktp_pemilik_sarana | K24: /legal_documents/company/5715/document_ktp_pemilik_sarana.jpeg | M24: pending | O24: Apotek Yani baru | P24: yanibaru07@gmail.com | Q24: document_npwp | R24: /legal_documents/company/3892/document_npwp.pdf | T24: pending | V24: PT. Sejahtera Harapan Tigas | W24: pbf.sehati@gmail.com | X24: document_sertifikasi_cdob | Y24: /legal_documents/company/4725/document_sertifikasi_cdob.PDF | Z24: 46116 | AA24: pending | AJ24: RSUD Lubuk Sikaping | AK24: rsudlubuksikaping1@gmail.com | AL24: document_sipa_sika_apoteker | AM24: /legal_documents/company/3997/document_sipa_sika_apoteker.pdf | AN24: 46091 | AO24: pending | AQ24: RSUD Lubuk Sikaping | AR24: rsudlubuksikaping1@gmail.com | AS24: document_siup | AT24: /legal_documents/company/3997/document_siup.pdf | AU24: 46091 | AV24: pending | AX24: Apotek Yani baru | AY24: yanibaru07@gmail.com | AZ24: document_stra_apoteker | BA24: /legal_documents/company/3892/document_stra_apoteker.pdf | BB24: 46032 | BC24: pending | BE24: PT. Oasis Mitra Alkes | BF24: oasismitraalkes@gmail.com | BG24: document_strttk | BH24: /legal_documents/company/5782/document_strttk.pdf | BI24: 45933 | BJ24: pending | BL24: APT GANESA | BM24: apotekganesasanglah@gmail.com | BN24: document_surat_izin_apotek | BO24: /legal_documents/company/2747/document_surat_izin_apotek.pdf | BP24: 46124 | BQ24: pending
A25: APOTEKKU HEALING PHARMACY MUNGGU | B25: apotekku.munggu@gmail.com | C25: document_foto_lokasi_bagunan_fisik | D25: /legal_documents/company/4059/document_foto_lokasi_bagunan_fisik.jpg | F25: pending | H25: APOTEK SITU FARMA | I25: medbizkftd+20003140@gmail.com | J25: document_ktp_pemilik_sarana | K25: /legal_documents/company/25849/document_ktp_pemilik_sarana.pdf | M25: pending | O25: APT. MONICA | P25: aptmonica96@gmail.com | Q25: document_npwp | R25: /legal_documents/company/4002/document_npwp.pdf | T25: pending | V25: PT. Karya Tri Andita | W25: freddyhidayatw@yahoo.com | X25: document_sertifikasi_cdob | Y25: /legal_documents/company/4734/document_sertifikasi_cdob.PDF | Z25: 45981 | AA25: pending | AJ25: Apotek Yani baru | AK25: yanibaru07@gmail.com | AL25: document_sipa_sika_apoteker | AM25: /legal_documents/company/3892/document_sipa_sika_apoteker.pdf | AN25: 46032 | AO25: pending | AQ25: Apotik winning | AR25: apotikwinning@gmail.com | AS25: document_siup | AT25: /legal_documents/company/3996/document_siup.jpeg | AU25: 46502 | AV25: pending | AX25: APT. MONICA | AY25: aptmonica96@gmail.com | AZ25: document_stra_apoteker | BA25: /legal_documents/company/4002/document_stra_apoteker.pdf | BB25: 46052 | BC25: pending | BE25: PT. Fitlab Utama Karya | BF25: radhityafebriansyah88@gmail.com | BG25: document_strttk | BH25: /legal_documents/company/6033/document_strttk.pdf | BI25: 46626 | BJ25: pending | BL25: APT. KESEHATAN PADJAJARAN | BM25: apotek.unpad@gmail.com | BN25: document_surat_izin_apotek | BO25: /legal_documents/company/3811/document_surat_izin_apotek.pdf | BP25: 47848 | BQ25: pending
A26: Bahana Medical Clinic | B26: andisumrianidarpan@gmail.com | C26: document_foto_lokasi_bagunan_fisik | D26: /legal_documents/company/4007/document_foto_lokasi_bagunan_fisik.jpg | F26: pending | H26: PT. Daun Teratai Herbalife | I26: rendydth@gmail.com | J26: document_ktp_pemilik_sarana | K26: /legal_documents/company/34614/document_ktp_pemilik_sarana.pdf | M26: pending | O26: Apotik Berkat | P26: amar160721@gmail.com | Q26: document_npwp | R26: /legal_documents/company/3925/document_npwp.jpg | T26: pending | V26: PT. Barotama Mulya Perkasa | W26: barotamamp21@gmail.com | X26: document_sertifikasi_cdob | Y26: /legal_documents/company/4767/document_sertifikasi_cdob.pdf | Z26: 45889 | AA26: pending | AJ26: APT. MONICA | AK26: aptmonica96@gmail.com | AL26: document_sipa_sika_apoteker | AM26: /legal_documents/company/4002/document_sipa_sika_apoteker.pdf | AN26: 46052 | AO26: pending | AQ26: Apotek Yani baru | AR26: yanibaru07@gmail.com | AS26: document_siup | AT26: /legal_documents/company/3892/document_siup.pdf | AU26: 46032 | AV26: pending | AX26: Apotik Berkat | AY26: amar160721@gmail.com | AZ26: document_stra_apoteker | BA26: /legal_documents/company/3925/document_stra_apoteker.jpg | BB26: 45854 | BC26: pending | BE26: PT. Gamma Abadi Mandiri | BF26: ptgammaabadimandirilpg@gmail.com | BG26: document_strttk | BH26: /legal_documents/company/6161/document_strttk.jpeg | BI26: 45566 | BJ26: pending | BL26: APT.BANTUAN | BM26: apotikbantuan@gmail.com | BN26: document_surat_izin_apotek | BO26: /legal_documents/company/3794/document_surat_izin_apotek.pdf | BP26: 45693 | BQ26: pending
A27: RSU BUNDA | B27: rsbundapwkt@gmail.com | C27: document_foto_lokasi_bagunan_fisik | D27: /legal_documents/company/4071/document_foto_lokasi_bagunan_fisik.jpg | F27: pending | H27: APOTEK ACHA FARMA II | I27: medbizkftd+10085798@gmail.com | J27: document_ktp_pemilik_sarana | K27: /legal_documents/company/20285/document_ktp_pemilik_sarana.png | M27: pending | O27: APT GANESA | P27: apotekganesasanglah@gmail.com | Q27: document_npwp | R27: /legal_documents/company/2747/document_npwp.pdf | T27: pending | V27: PT. Praba Baraka Jaya | W27: ptprababarakajaya@gmail.com | X27: document_sertifikasi_cdob | Y27: /legal_documents/company/4776/document_sertifikasi_cdob.PDF | Z27: 46124 | AA27: pending | AJ27: Apotik Berkat | AK27: amar160721@gmail.com | AL27: document_sipa_sika_apoteker | AM27: /legal_documents/company/3925/document_sipa_sika_apoteker.jpg | AN27: 45854 | AO27: pending | AQ27: APT. MONICA | AR27: aptmonica96@gmail.com | AS27: document_siup | AT27: /legal_documents/company/4002/document_siup.pdf | AU27: 46052 | AV27: pending | AX27: APT GANESA | AY27: apotekganesasanglah@gmail.com | AZ27: document_stra_apoteker | BA27: /legal_documents/company/2747/document_stra_apoteker.pdf | BB27: 46124 | BC27: pending | BE27: PT. Wuni Sejahtera | BF27: wunisejahtera212@gmail.com | BG27: document_strttk | BH27: /legal_documents/company/1926/document_strttk.pdf | BI27: 46751 | BJ27: pending | BL27: APOTEK MUSLIMAH FARMA | BM27: aptmuslimahfarma@gmail.com | BN27: document_surat_izin_apotek | BO27: /legal_documents/company/4017/document_surat_izin_apotek.pdf | BP27: 46185 | BQ27: pending
A28: Apotek Selayang | B28: baharlubis786@gmail.com | C28: document_foto_lokasi_bagunan_fisik | D28: /legal_documents/company/3874/document_foto_lokasi_bagunan_fisik.pdf | F28: pending | H28: APOTEK YULIA FARMA | I28: medbizkftd+10077986@gmail.com | J28: document_ktp_pemilik_sarana | K28: /legal_documents/company/14000/document_ktp_pemilik_sarana.jpeg | M28: pending | O28: RS. NAILI DBS | P28: farmasi.ndbs@gmail.com | Q28: document_npwp | R28: /legal_documents/company/3497/document_npwp.jpg | T28: pending | V28: PT Trisnia Pharma Medika | W28: trisinapharmamedika@gmail.com | X28: document_sertifikasi_cdob | Y28: /legal_documents/company/4771/document_sertifikasi_cdob.png | Z28: 45831 | AA28: pending | AJ28: APT. KRAJAN FARMA KRIAN | AK28: apotekkrajan@gmail.com | AL28: document_sipa_sika_apoteker | AM28: /legal_documents/company/3945/document_sipa_sika_apoteker.jpg | AN28: 46215 | AO28: pending | AQ28: Apotik Berkat | AR28: amar160721@gmail.com | AS28: document_siup | AT28: /legal_documents/company/3925/document_siup.jpg | AU28: 46299 | AV28: pending | AX28: RS. NAILI DBS | AY28: farmasi.ndbs@gmail.com | AZ28: document_stra_apoteker | BA28: /legal_documents/company/3497/document_stra_apoteker.jpg | BB28: 46046 | BC28: pending | BE28: PT. BUNDA GLOBAL PHARMA | BF28: drafdi@gmail.com | BG28: document_strttk | BH28: /legal_documents/company/6272/document_strttk.pdf | BI28: 45237 | BJ28: pending | BL28: APT. CIROYOM | BM28: apotekating11@gmail.com | BN28: document_surat_izin_apotek | BO28: /legal_documents/company/3857/document_surat_izin_apotek.pdf | BP28: 45531 | BQ28: pending
